Workbook

Sheet Dashboard
A1: Trading Performance Dashboard
A2: Account 91404 (THM00601) • Market FUT, Reg • Currency PKR • Generated 16-Oct-2026 11:35
A4: Latest Trading Day: | B4: =MAX('Daily Summary'!$A$5:$A$404) -> 46311
A6: LATEST TRADING DAY | D6: PERFORMANCE SNAPSHOT
A7: Buy Value | B7: ='Daily Summary'!E40 -> 4845060 | D7: Period | E7: Net P&L (PKR) | F7: Return on Buy
A8: Sell Value | B8: ='Daily Summary'!F40 -> 4855610 | D8: MTD (Oct 2026) | E8: ='MTD Summary'!$B$19 -> 39790.636 | F8: ='MTD Summary'!$B$20 -> 0.00035470732
A9: Gross P&L | B9: ='Daily Summary'!G40 -> 10550 | D9: QTD (Q4 2026) | E9: ='QTD Summary'!$B$19 -> 39790.636 | F9: ='QTD Summary'!$B$20 -> 0.00035470732
A10: Commission | B10: ='Daily Summary'!H40 -> 1578.0732 | D10: YTD (2026) | E10: ='YTD Summary'!$B$19 -> 193263.61 | F10: ='YTD Summary'!$B$20 -> 0.00047928714
A11: SST (13%) | B11: ='Daily Summary'!I40 -> 205.14952
A12: Net P&L | B12: ='Daily Summary'!K40 -> 8766.7772 | D12: ACTIVITY — ALL IMPORTED DATA
A13: Return on Buy | B13: ='Daily Summary'!L40 -> 0.0018094259 | D13: Total Traded Volume (PKR) | E13: ='Daily Summary'!$E$41+'Daily Summary'!$F$41 -> 8.0680211e+08
D14: Executions | E14: 2742
D15: Symbols | E15: =COUNTA('Symbol Performance'!$A$5:$A$61) -> 57
D16: Trading Days | E16: =COUNT('Daily Summary'!$A$5:$A$404) -> 36
D18: BEST / WORST SYMBOL (Net P&L, all dates)
D19: Best Symbol | E19: =INDEX('Symbol Performance'!$A$5:$A$61,MATCH(MAX('Symbol Performance'!$I$5:$I$61),'Symbol Performance'!$I$5:$I$61,0)) -> PRL-AUG | F19: =MAX('Symbol Performance'!$I$5:$I$61) -> 37651.077
D20: Worst Symbol | E20: =INDEX('Symbol Performance'!$A$5:$A$61,MATCH(MIN('Symbol Performance'!$I$5:$I$61),'Symbol Performance'!$I$5:$I$61,0)) -> OGDC-OCTB | F20: =MIN('Symbol Performance'!$I$5:$I$61) -> -3184.0584
A22: • Methodology: Gross P&L = Sell Value − Buy Value (intraday buy/sell flow; Short Sell counts as SELL).
A23: • Commission is sell-side only: sell rate < 54 → 0.0175 paisa/share; ≥ 54 → 0.0325% of sell value. SST = 13% of commission.
A24: • Net P&L = Gross P&L − Commission − SST. Return on Buy = Net P&L ÷ Buy Value (recomputed from totals, never averaged).
A25: • Position status through 16-Oct-2026: all symbols flat (net quantity 0) on every trading day.
A26: • This is a flow-based summary, not FIFO/average-cost realized-position accounting. See the Settings sheet.

Sheet Daily Summary
A1: Daily Summary
A2: One row per trading date — linked live to the Daily Trade Summary blocks.
A4: Date | B4: Buy Qty | C4: Sell Qty | D4: Net Qty | E4: Buy Value (PKR) | F4: Sell Value (PKR) | G4: Gross P&L (PKR) | H4: Commission (PKR) | I4: SST (PKR) | J4: Total Charges (PKR) | K4: Net P&L (PKR) | L4: Return on Buy
A5: 46251 | B5: ='Daily Trade Summary'!B21 -> 70500 | C5: ='Daily Trade Summary'!E21 -> 70500 | D5: ='Daily Trade Summary'!I21 -> 0 | E5: ='Daily Trade Summary'!C21 -> 18267720 | F5: ='Daily Trade Summary'!F21 -> 18287930 | G5: ='Daily Trade Summary'!J21 -> 20210 | H5: ='Daily Trade Summary'!L21 -> 5943.5773 | I5: ='Daily Trade Summary'!M21 -> 772.66504 | J5: ='Daily Trade Summary'!N21 -> 6716.2423 | K5: ='Daily Trade Summary'!O21 -> 13493.758 | L5: =IF($E5=0,"",$K5/$E5) -> 0.00073866677
A6: 46252 | B6: ='Daily Trade Summary'!B47 -> 125640 | C6: ='Daily Trade Summary'!E47 -> 125640 | D6: ='Daily Trade Summary'!I47 -> 0 | E6: ='Daily Trade Summary'!C47 -> 21984905 | F6: ='Daily Trade Summary'!F47 -> 22001335 | G6: ='Daily Trade Summary'!J47 -> 16430 | H6: ='Daily Trade Summary'!L47 -> 6920.3714 | I6: ='Daily Trade Summary'!M47 -> 899.64828 | J6: ='Daily Trade Summary'!N47 -> 7820.0197 | K6: ='Daily Trade Summary'!O47 -> 8609.9803 | L6: =IF($E6=0,"",$K6/$E6) -> 0.00039163146
A7: 46253 | B7: ='Daily Trade Summary'!B70 -> 96000 | C7: ='Daily Trade Summary'!E70 -> 96000 | D7: ='Daily Trade Summary'!I70 -> 0 | E7: ='Daily Trade Summary'!C70 -> 12039745 | F7: ='Daily Trade Summary'!F70 -> 12062720 | G7: ='Daily Trade Summary'!J70 -> 22975 | H7: ='Daily Trade Summary'!L70 -> 3851.2528 | I7: ='Daily Trade Summary'!M70 -> 500.66286 | J7: ='Daily Trade Summary'!N70 -> 4351.9156 | K7: ='Daily Trade Summary'!O70 -> 18623.084 | L7: =IF($E7=0,"",$K7/$E7) -> 0.0015468006
A8: 46254 | B8: ='Daily Trade Summary'!B94 -> 63500 | C8: ='Daily Trade Summary'!E94 -> 63500 | D8: ='Daily Trade Summary'!I94 -> 0 | E8: ='Daily Trade Summary'!C94 -> 10062968 | F8: ='Daily Trade Summary'!F94 -> 10084865 | G8: ='Daily Trade Summary'!J94 -> 21896.51 | H8: ='Daily Trade Summary'!L94 -> 3277.581 | I8: ='Daily Trade Summary'!M94 -> 426.08553 | J8: ='Daily Trade Summary'!N94 -> 3703.6665 | K8: ='Daily Trade Summary'!O94 -> 18192.844 | L8: =IF($E8=0,"",$K8/$E8) -> 0.0018079004
A9: 46255 | B9: ='Daily Trade Summary'!B117 -> 45357 | C9: ='Daily Trade Summary'!E117 -> 45357 | D9: ='Daily Trade Summary'!I117 -> 0 | E9: ='Daily Trade Summary'!C117 -> 8763520 | F9: ='Daily Trade Summary'!F117 -> 8772484.3 | G9: ='Daily Trade Summary'!J117 -> 8964.29 | H9: ='Daily Trade Summary'!L117 -> 2851.0574 | I9: ='Daily Trade Summary'!M117 -> 370.63746 | J9: ='Daily Trade Summary'!N117 -> 3221.6948 | K9: ='Daily Trade Summary'!O117 -> 5742.5952 | L9: =IF($E9=0,"",$K9/$E9) -> 0.00065528408
A10: 46258 | B10: ='Daily Trade Summary'!B140 -> 84004 | C10: ='Daily Trade Summary'!E140 -> 84004 | D10: ='Daily Trade Summary'!I140 -> 0 | E10: ='Daily Trade Summary'!C140 -> 13130113 | F10: ='Daily Trade Summary'!F140 -> 13155567 | G10: ='Daily Trade Summary'!J140 -> 25454.29 | H10: ='Daily Trade Summary'!L140 -> 4275.5592 | I10: ='Daily Trade Summary'!M140 -> 555.8227 | J10: ='Daily Trade Summary'!N140 -> 4831.3819 | K10: ='Daily Trade Summary'!O140 -> 20622.908 | L10: =IF($E10=0,"",$K10/$E10) -> 0.0015706574
A11: 46261 | B11: ='Daily Trade Summary'!B157 -> 26500 | C11: ='Daily Trade Summary'!E157 -> 26500 | D11: ='Daily Trade Summary'!I157 -> 0 | E11: ='Daily Trade Summary'!C157 -> 2407645 | F11: ='Daily Trade Summary'!F157 -> 2404525 | G11: ='Daily Trade Summary'!J157 -> -3120 | H11: ='Daily Trade Summary'!L157 -> 781.47063 | I11: ='Daily Trade Summary'!M157 -> 101.59118 | J11: ='Daily Trade Summary'!N157 -> 883.06181 | K11: ='Daily Trade Summary'!O157 -> -4003.0618 | L11: =IF($E11=0,"",$K11/$E11) -> -0.0016626462
A12: 46265 | B12: ='Daily Trade Summary'!B179 -> 51500 | C12: ='Daily Trade Summary'!E179 -> 51500 | D12: ='Daily Trade Summary'!I179 -> 0 | E12: ='Daily Trade Summary'!C179 -> 18280837 | F12: ='Daily Trade Summary'!F179 -> 18292560 | G12: ='Daily Trade Summary'!J179 -> 11723.11 | H12: ='Daily Trade Summary'!L179 -> 5945.082 | I12: ='Daily Trade Summary'!M179 -> 772.86066 | J12: ='Daily Trade Summary'!N179 -> 6717.9427 | K12: ='Daily Trade Summary'!O179 -> 5005.1673 | L12: =IF($E12=0,"",$K12/$E12) -> 0.00027379312
A13: 46266 | B13: ='Daily Trade Summary'!B203 -> 40920 | C13: ='Daily Trade Summary'!E203 -> 40920 | D13: ='Daily Trade Summary'!I203 -> 0 | E13: ='Daily Trade Summary'!C203 -> 13686449 | F13: ='Daily Trade Summary'!F203 -> 13711864 | G13: ='Daily Trade Summary'!J203 -> 25415.3 | H13: ='Daily Trade Summary'!L203 -> 4456.3559 | I13: ='Daily Trade Summary'!M203 -> 579.32627 | J13: ='Daily Trade Summary'!N203 -> 5035.6822 | K13: ='Daily Trade Summary'!O203 -> 20379.618 | L13: =IF($E13=0,"",$K13/$E13) -> 0.0014890362
A14: 46267 | B14: ='Daily Trade Summary'!B223 -> 115000 | C14: ='Daily Trade Summary'!E223 -> 115000 | D14: ='Daily Trade Summary'!I223 -> 0 | E14: ='Daily Trade Summary'!C223 -> 14853375 | F14: ='Daily Trade Summary'!F223 -> 14863825 | G14: ='Daily Trade Summary'!J223 -> 10450.36 | H14: ='Daily Trade Summary'!L223 -> 4830.7432 | I14: ='Daily Trade Summary'!M223 -> 627.99662 | J14: ='Daily Trade Summary'!N223 -> 5458.7399 | K14: ='Daily Trade Summary'!O223 -> 4991.6201 | L14: =IF($E14=0,"",$K14/$E14) -> 0.00033605966
A15: 46268 | B15: ='Daily Trade Summary'!B249 -> 85000 | C15: ='Daily Trade Summary'!E249 -> 85000 | D15: ='Daily Trade Summary'!I249 -> 0 | E15: ='Daily Trade Summary'!C249 -> 15859132 | F15: ='Daily Trade Summary'!F249 -> 15867402 | G15: ='Daily Trade Summary'!J249 -> 8269.59 | H15: ='Daily Trade Summary'!L249 -> 5156.9056 | I15: ='Daily Trade Summary'!M249 -> 670.39772 | J15: ='Daily Trade Summary'!N249 -> 5827.3033 | K15: ='Daily Trade Summary'!O249 -> 2442.2867 | L15: =IF($E15=0,"",$K15/$E15) -> 0.00015399876
A16: 46269 | B16: ='Daily Trade Summary'!B272 -> 139200 | C16: ='Daily Trade Summary'!E272 -> 139200 | D16: ='Daily Trade Summary'!I272 -> 0 | E16: ='Daily Trade Summary'!C272 -> 22870427 | F16: ='Daily Trade Summary'!F272 -> 22877215 | G16: ='Daily Trade Summary'!J272 -> 6788.43 | H16: ='Daily Trade Summary'!L272 -> 7435.0949 | I16: ='Daily Trade Summary'!M272 -> 966.56233 | J16: ='Daily Trade Summary'!N272 -> 8401.6572 | K16: ='Daily Trade Summary'!O272 -> -1613.2272 | L16: =IF($E16=0,"",$K16/$E16) -> -7.0537697e-05
A17: 46272 | B17: ='Daily Trade Summary'!B292 -> 22051 | C17: ='Daily Trade Summary'!E292 -> 22051 | D17: ='Daily Trade Summary'!I292 -> 0 | E17: ='Daily Trade Summary'!C292 -> 3194849.5 | F17: ='Daily Trade Summary'!F292 -> 3205253.5 | G17: ='Daily Trade Summary'!J292 -> 10403.97 | H17: ='Daily Trade Summary'!L292 -> 1041.7074 | I17: ='Daily Trade Summary'!M292 -> 135.42196 | J17: ='Daily Trade Summary'!N292 -> 1177.1293 | K17: ='Daily Trade Summary'!O292 -> 9226.8407 | L17: =IF($E17=0,"",$K17/$E17) -> 0.0028880361
A18: 46273 | B18: ='Daily Trade Summary'!B314 -> 67000 | C18: ='Daily Trade Summary'!E314 -> 67000 | D18: ='Daily Trade Summary'!I314 -> 0 | E18: ='Daily Trade Summary'!C314 -> 11580825 | F18: ='Daily Trade Summary'!F314 -> 11593195 | G18: ='Daily Trade Summary'!J314 -> 12370 | H18: ='Daily Trade Summary'!L314 -> 3716.4609 | I18: ='Daily Trade Summary'!M314 -> 483.13991 | J18: ='Daily Trade Summary'!N314 -> 4199.6008 | K18: ='Daily Trade Summary'!O314 -> 8170.3992 | L18: =IF($E18=0,"",$K18/$E18) -> 0.00070551098
A19: 46274 | B19: ='Daily Trade Summary'!B334 -> 51953 | C19: ='Daily Trade Summary'!E334 -> 51953 | D19: ='Daily Trade Summary'!I334 -> 0 | E19: ='Daily Trade Summary'!C334 -> 4936491 | F19: ='Daily Trade Summary'!F334 -> 4940816 | G19: ='Daily Trade Summary'!J334 -> 4324.98 | H19: ='Daily Trade Summary'!L334 -> 1605.7652 | I19: ='Daily Trade Summary'!M334 -> 208.74948 | J19: ='Daily Trade Summary'!N334 -> 1814.5147 | K19: ='Daily Trade Summary'!O334 -> 2510.4653 | L19: =IF($E19=0,"",$K19/$E19) -> 0.0005085526
A20: 46275 | B20: ='Daily Trade Summary'!B355 -> 25405 | C20: ='Daily Trade Summary'!E355 -> 25405 | D20: ='Daily Trade Summary'!I355 -> 0 | E20: ='Daily Trade Summary'!C355 -> 3843124.4 | F20: ='Daily Trade Summary'!F355 -> 3839233.9 | G20: ='Daily Trade Summary'!J355 -> -3890.53 | H20: ='Daily Trade Summary'!L355 -> 1189.7124 | I20: ='Daily Trade Summary'!M355 -> 154.66261 | J20: ='Daily Trade Summary'!N355 -> 1344.375 | K20: ='Daily Trade Summary'!O355 -> -5234.905 | L20: =IF($E20=0,"",$K20/$E20) -> -0.0013621482
A21: 46276 | B21: ='Daily Trade Summary'!B375 -> 52593 | C21: ='Daily Trade Summary'!E375 -> 52593 | D21: ='Daily Trade Summary'!I375 -> 0 | E21: ='Daily Trade Summary'!C375 -> 6080555.6 | F21: ='Daily Trade Summary'!F375 -> 6086289 | G21: ='Daily Trade Summary'!J375 -> 5733.48 | H21: ='Daily Trade Summary'!L375 -> 1978.0439 | I21: ='Daily Trade Summary'!M375 -> 257.14571 | J21: ='Daily Trade Summary'!N375 -> 2235.1897 | K21: ='Daily Trade Summary'!O375 -> 3498.2903 | L21: =IF($E21=0,"",$K21/$E21) -> 0.00057532413
A22: 46279 | B22: ='Daily Trade Summary'!B400 -> 68500 | C22: ='Daily Trade Summary'!E400 -> 68500 | D22: ='Daily Trade Summary'!I400 -> 0 | E22: ='Daily Trade Summary'!C400 -> 11322640 | F22: ='Daily Trade Summary'!F400 -> 11331895 | G22: ='Daily Trade Summary'!J400 -> 9254.58 | H22: ='Daily Trade Summary'!L400 -> 3682.8659 | I22: ='Daily Trade Summary'!M400 -> 478.77256 | J22: ='Daily Trade Summary'!N400 -> 4161.6384 | K22: ='Daily Trade Summary'!O400 -> 5092.9416 | L22: =IF($E22=0,"",$K22/$E22) -> 0.00044980158
A23: 46280 | B23: ='Daily Trade Summary'!B418 -> 18000 | C23: ='Daily Trade Summary'!E418 -> 18000 | D23: ='Daily Trade Summary'!I418 -> 0 | E23: ='Daily Trade Summary'!C418 -> 2928580 | F23: ='Daily Trade Summary'!F418 -> 2930140 | G23: ='Daily Trade Summary'!J418 -> 1560 | H23: ='Daily Trade Summary'!L418 -> 952.2955 | I23: ='Daily Trade Summary'!M418 -> 123.79842 | J23: ='Daily Trade Summary'!N418 -> 1076.0939 | K23: ='Daily Trade Summary'!O418 -> 483.90609 | L23: =IF($E23=0,"",$K23/$E23) -> 0.00016523574
A24: 46281 | B24: ='Daily Trade Summary'!B442 -> 43500 | C24: ='Daily Trade Summary'!E442 -> 43500 | D24: ='Daily Trade Summary'!I442 -> 0 | E24: ='Daily Trade Summary'!C442 -> 8237815.7 | F24: ='Daily Trade Summary'!F442 -> 8236390 | G24: ='Daily Trade Summary'!J442 -> -1425.65 | H24: ='Daily Trade Summary'!L442 -> 2676.8268 | I24: ='Daily Trade Summary'!M442 -> 347.98748 | J24: ='Daily Trade Summary'!N442 -> 3024.8142 | K24: ='Daily Trade Summary'!O442 -> -4450.4642 | L24: =IF($E24=0,"",$K24/$E24) -> -0.0005402481
A25: 46282 | B25: ='Daily Trade Summary'!B468 -> 57500 | C25: ='Daily Trade Summary'!E468 -> 57500 | D25: ='Daily Trade Summary'!I468 -> 0 | E25: ='Daily Trade Summary'!C468 -> 10564945 | F25: ='Daily Trade Summary'!F468 -> 10567938 | G25: ='Daily Trade Summary'!J468 -> 2992.65 | H25: ='Daily Trade Summary'!L468 -> 3434.5797 | I25: ='Daily Trade Summary'!M468 -> 446.49537 | J25: ='Daily Trade Summary'!N468 -> 3881.0751 | K25: ='Daily Trade Summary'!O468 -> -888.4251 | L25: =IF($E25=0,"",$K25/$E25) -> -8.4091787e-05
A26: 46283 | B26: ='Daily Trade Summary'!B495 -> 94719 | C26: ='Daily Trade Summary'!E495 -> 94719 | D26: ='Daily Trade Summary'!I495 -> 0 | E26: ='Daily Trade Summary'!C495 -> 14436906 | F26: ='Daily Trade Summary'!F495 -> 14447051 | G26: ='Daily Trade Summary'!J495 -> 10145.52 | H26: ='Daily Trade Summary'!L495 -> 4695.2917 | I26: ='Daily Trade Summary'!M495 -> 610.38792 | J26: ='Daily Trade Summary'!N495 -> 5305.6796 | K26: ='Daily Trade Summary'!O495 -> 4839.8404 | L26: =IF($E26=0,"",$K26/$E26) -> 0.00033524083
A27: 46293 | B27: ='Daily Trade Summary'!B521 -> 143000 | C27: ='Daily Trade Summary'!E521 -> 143000 | D27: ='Daily Trade Summary'!I521 -> 0 | E27: ='Daily Trade Summary'!C521 -> 15324771 | F27: ='Daily Trade Summary'!F521 -> 15336029 | G27: ='Daily Trade Summary'!J521 -> 11258.44 | H27: ='Daily Trade Summary'!L521 -> 4771.0938 | I27: ='Daily Trade Summary'!M521 -> 620.2422 | J27: ='Daily Trade Summary'!N521 -> 5391.336 | K27: ='Daily Trade Summary'!O521 -> 5867.104 | L27: =IF($E27=0,"",$K27/$E27) -> 0.00038285101
A28: 46294 | B28: ='Daily Trade Summary'!B542 -> 97000 | C28: ='Daily Trade Summary'!E542 -> 97000 | D28: ='Daily Trade Summary'!I542 -> 0 | E28: ='Daily Trade Summary'!C542 -> 12460825 | F28: ='Daily Trade Summary'!F542 -> 12473955 | G28: ='Daily Trade Summary'!J542 -> 13130 | H28: ='Daily Trade Summary'!L542 -> 4006.7798 | I28: ='Daily Trade Summary'!M542 -> 520.88137 | J28: ='Daily Trade Summary'!N542 -> 4527.6611 | K28: ='Daily Trade Summary'!O542 -> 8602.3389 | L28: =IF($E28=0,"",$K28/$E28) -> 0.00069035067
A29: 46295 | B29: ='Daily Trade Summary'!B563 -> 114485 | C29: ='Daily Trade Summary'!E563 -> 114485 | D29: ='Daily Trade Summary'!I563 -> 0 | E29: ='Daily Trade Summary'!C563 -> 13933421 | F29: ='Daily Trade Summary'!F563 -> 13941808 | G29: ='Daily Trade Summary'!J563 -> 8387.2 | H29: ='Daily Trade Summary'!L563 -> 4531.0876 | I29: ='Daily Trade Summary'!M563 -> 589.04139 | J29: ='Daily Trade Summary'!N563 -> 5120.129 | K29: ='Daily Trade Summary'!O563 -> 3267.071 | L29: =IF($E29=0,"",$K29/$E29) -> 0.0002344773
A30: 46296 | B30: ='Daily Trade Summary'!B585 -> 61500 | C30: ='Daily Trade Summary'!E585 -> 61500 | D30: ='Daily Trade Summary'!I585 -> 0 | E30: ='Daily Trade Summary'!C585 -> 9592760 | F30: ='Daily Trade Summary'!F585 -> 9603580 | G30: ='Daily Trade Summary'!J585 -> 10820 | H30: ='Daily Trade Summary'!L585 -> 3121.1635 | I30: ='Daily Trade Summary'!M585 -> 405.75126 | J30: ='Daily Trade Summary'!N585 -> 3526.9148 | K30: ='Daily Trade Summary'!O585 -> 7293.0852 | L30: =IF($E30=0,"",$K30/$E30) -> 0.00076026975
A31: 46297 | B31: ='Daily Trade Summary'!B605 -> 35500 | C31: ='Daily Trade Summary'!E605 -> 35500 | D31: ='Daily Trade Summary'!I605 -> 0 | E31: ='Daily Trade Summary'!C605 -> 8710670 | F31: ='Daily Trade Summary'!F605 -> 8714260 | G31: ='Daily Trade Summary'!J605 -> 3590 | H31: ='Daily Trade Summary'!L605 -> 2832.1345 | I31: ='Daily Trade Summary'!M605 -> 368.17748 | J31: ='Daily Trade Summary'!N605 -> 3200.312 | K31: ='Daily Trade Summary'!O605 -> 389.68802 | L31: =IF($E31=0,"",$K31/$E31) -> 4.4736859e-05
A32: 46300 | B32: ='Daily Trade Summary'!B625 -> 60000 | C32: ='Daily Trade Summary'!E625 -> 60000 | D32: ='Daily Trade Summary'!I625 -> 0 | E32: ='Daily Trade Summary'!C625 -> 6890615 | F32: ='Daily Trade Summary'!F625 -> 6893846.3 | G32: ='Daily Trade Summary'!J625 -> 3231.33 | H32: ='Daily Trade Summary'!L625 -> 2240.5001 | I32: ='Daily Trade Summary'!M625 -> 291.26501 | J32: ='Daily Trade Summary'!N625 -> 2531.7651 | K32: ='Daily Trade Summary'!O625 -> 699.56494 | L32: =IF($E32=0,"",$K32/$E32) -> 0.00010152431
A33: 46301 | B33: ='Daily Trade Summary'!B652 -> 126235 | C33: ='Daily Trade Summary'!E652 -> 126235 | D33: ='Daily Trade Summary'!I652 -> 0 | E33: ='Daily Trade Summary'!C652 -> 19094354 | F33: ='Daily Trade Summary'!F652 -> 19099591 | G33: ='Daily Trade Summary'!J652 -> 5237.26 | H33: ='Daily Trade Summary'!L652 -> 5871.6662 | I33: ='Daily Trade Summary'!M652 -> 763.31661 | J33: ='Daily Trade Summary'!N652 -> 6634.9828 | K33: ='Daily Trade Summary'!O652 -> -1397.7228 | L33: =IF($E33=0,"",$K33/$E33) -> -7.3200846e-05
A34: 46302 | B34: ='Daily Trade Summary'!B678 -> 114400 | C34: ='Daily Trade Summary'!E678 -> 114400 | D34: ='Daily Trade Summary'!I678 -> 0 | E34: ='Daily Trade Summary'!C678 -> 15990980 | F34: ='Daily Trade Summary'!F678 -> 16004711 | G34: ='Daily Trade Summary'!J678 -> 13730.84 | H34: ='Daily Trade Summary'!L678 -> 5201.5311 | I34: ='Daily Trade Summary'!M678 -> 676.19904 | J34: ='Daily Trade Summary'!N678 -> 5877.7301 | K34: ='Daily Trade Summary'!O678 -> 7853.1099 | L34: =IF($E34=0,"",$K34/$E34) -> 0.00049109622
A35: 46303 | B35: ='Daily Trade Summary'!B700 -> 62859 | C35: ='Daily Trade Summary'!E700 -> 62859 | D35: ='Daily Trade Summary'!I700 -> 0 | E35: ='Daily Trade Summary'!C700 -> 9701743.2 | F35: ='Daily Trade Summary'!F700 -> 9715115.4 | G35: ='Daily Trade Summary'!J700 -> 13372.19 | H35: ='Daily Trade Summary'!L700 -> 3157.4125 | I35: ='Daily Trade Summary'!M700 -> 410.46363 | J35: ='Daily Trade Summary'!N700 -> 3567.8761 | K35: ='Daily Trade Summary'!O700 -> 9804.3139 | L35: =IF($E35=0,"",$K35/$E35) -> 0.0010105724
A36: 46304 | B36: ='Daily Trade Summary'!B718 -> 28000 | C36: ='Daily Trade Summary'!E718 -> 28000 | D36: ='Daily Trade Summary'!I718 -> 0 | E36: ='Daily Trade Summary'!C718 -> 3975465 | F36: ='Daily Trade Summary'!F718 -> 3982225 | G36: ='Daily Trade Summary'!J718 -> 6760 | H36: ='Daily Trade Summary'!L718 -> 1294.2231 | I36: ='Daily Trade Summary'!M718 -> 168.24901 | J36: ='Daily Trade Summary'!N718 -> 1462.4721 | K36: ='Daily Trade Summary'!O718 -> 5297.5279 | L36: =IF($E36=0,"",$K36/$E36) -> 0.0013325555
A37: 46307 | B37: ='Daily Trade Summary'!B741 -> 119500 | C37: ='Daily Trade Summary'!E741 -> 119500 | D37: ='Daily Trade Summary'!I741 -> 0 | E37: ='Daily Trade Summary'!C741 -> 13087568 | F37: ='Daily Trade Summary'!F741 -> 13093430 | G37: ='Daily Trade Summary'!J741 -> 5862 | H37: ='Daily Trade Summary'!L741 -> 4088.782 | I37: ='Daily Trade Summary'!M741 -> 531.54166 | J37: ='Daily Trade Summary'!N741 -> 4620.3237 | K37: ='Daily Trade Summary'!O741 -> 1241.6763 | L37: =IF($E37=0,"",$K37/$E37) -> 9.487449e-05
A38: 46308 | B38: ='Daily Trade Summary'!B761 -> 111000 | C38: ='Daily Trade Summary'!E761 -> 111000 | D38: ='Daily Trade Summary'!I761 -> 0 | E38: ='Daily Trade Summary'!C761 -> 8618263 | F38: ='Daily Trade Summary'!F761 -> 8617447 | G38: ='Daily Trade Summary'!J761 -> -816 | H38: ='Daily Trade Summary'!L761 -> 2112.7472 | I38: ='Daily Trade Summary'!M761 -> 274.65713 | J38: ='Daily Trade Summary'!N761 -> 2387.4043 | K38: ='Daily Trade Summary'!O761 -> -3203.4043 | L38: =IF($E38=0,"",$K38/$E38) -> -0.00037169953
A39: 46310 | B39: ='Daily Trade Summary'!B782 -> 72500 | C39: ='Daily Trade Summary'!E782 -> 72500 | D39: ='Daily Trade Summary'!I782 -> 0 | E39: ='Daily Trade Summary'!C782 -> 11671305 | F39: ='Daily Trade Summary'!F782 -> 11678640 | G39: ='Daily Trade Summary'!J782 -> 7335 | H39: ='Daily Trade Summary'!L782 -> 3795.558 | I39: ='Daily Trade Summary'!M782 -> 493.42254 | J39: ='Daily Trade Summary'!N782 -> 4288.9805 | K39: ='Daily Trade Summary'!O782 -> 3046.0195 | L39: =IF($E39=0,"",$K39/$E39) -> 0.00026098362
A40: 46311 | B40: ='Daily Trade Summary'!B803 -> 22500 | C40: ='Daily Trade Summary'!E803 -> 22500 | D40: ='Daily Trade Summary'!I803 -> 0 | E40: ='Daily Trade Summary'!C803 -> 4845060 | F40: ='Daily Trade Summary'!F803 -> 4855610 | G40: ='Daily Trade Summary'!J803 -> 10550 | H40: ='Daily Trade Summary'!L803 -> 1578.0732 | I40: ='Daily Trade Summary'!M803 -> 205.14952 | J40: ='Daily Trade Summary'!N803 -> 1783.2228 | K40: ='Daily Trade Summary'!O803 -> 8766.7772 | L40: =IF($E40=0,"",$K40/$E40) -> 0.0018094259
A41: TOTAL | B41: =SUM(B5:B40) -> 2612821 | C41: =SUM(C5:C40) -> 2612821 | D41: =$B41-$C41 -> 0 | E41: =SUM(E5:E40) -> 4.0323137e+08 | F41: =SUM(F5:F40) -> 4.0357074e+08 | G41: =SUM(G5:G40) -> 339374.14 | H41: =SUM(H5:H40) -> 129301.35 | I41: =SUM(I5:I40) -> 16809.176 | J41: =SUM(J5:J40) -> 146110.53 | K41: =SUM(K5:K40) -> 193263.61 | L41: =IF($E41=0,"",$K41/$E41) -> 0.00047928714

Sheet MTD Summary
A1: Month-to-Date — October 2026
A2: Live SUMIFS over the Daily Summary, bounded by the period dates below.
A4: Period Start (calendar): | B4: 46296
A5: Period End (latest trade): | B5: =MAX('Daily Summary'!$A$5:$A$404) -> 46311
A6: First Trading Day in Period: | B6: =IFERROR(IF(INDEX('Daily Summary'!$A$5:$A$404,COUNTIF('Daily Summary'!$A$5:$A$404,"<"&$B$4)+1)>$B$5,"—",INDEX('Daily Summary'!$A$5:$A$404,COUNTIF('Daily Summary'!$A$5:$A$404,"<"&$B$4)+1)),"—") -> 46296
A7: Trading Days: | B7: =COUNTIFS('Daily Summary'!$A$5:$A$404,">="&$B$4,'Daily Summary'!$A$5:$A$404,"<="&$B$5) -> 11
A9: Metric | B9: Value
A10: Buy Quantity | B10: =SUMIFS('Daily Summary'!$B$5:$B$404,'Daily Summary'!$A$5:$A$404,">="&$B$4,'Daily Summary'!$A$5:$A$404,"<="&$B$5) -> 813994
A11: Sell Quantity | B11: =SUMIFS('Daily Summary'!$C$5:$C$404,'Daily Summary'!$A$5:$A$404,">="&$B$4,'Daily Summary'!$A$5:$A$404,"<="&$B$5) -> 813994
A12: Net Quantity | B12: =SUMIFS('Daily Summary'!$D$5:$D$404,'Daily Summary'!$A$5:$A$404,">="&$B$4,'Daily Summary'!$A$5:$A$404,"<="&$B$5) -> 0
A13: Buy Value (PKR) | B13: =SUMIFS('Daily Summary'!$E$5:$E$404,'Daily Summary'!$A$5:$A$404,">="&$B$4,'Daily Summary'!$A$5:$A$404,"<="&$B$5) -> 1.1217878e+08
A14: Sell Value (PKR) | B14: =SUMIFS('Daily Summary'!$F$5:$F$404,'Daily Summary'!$A$5:$A$404,">="&$B$4,'Daily Summary'!$A$5:$A$404,"<="&$B$5) -> 1.1225846e+08
A15: Gross P&L (PKR) | B15: =SUMIFS('Daily Summary'!$G$5:$G$404,'Daily Summary'!$A$5:$A$404,">="&$B$4,'Daily Summary'!$A$5:$A$404,"<="&$B$5) -> 79672.62
A16: Commission (PKR) | B16: =SUMIFS('Daily Summary'!$H$5:$H$404,'Daily Summary'!$A$5:$A$404,">="&$B$4,'Daily Summary'!$A$5:$A$404,"<="&$B$5) -> 35293.791
A17: SST (PKR) | B17: =SUMIFS('Daily Summary'!$I$5:$I$404,'Daily Summary'!$A$5:$A$404,">="&$B$4,'Daily Summary'!$A$5:$A$404,"<="&$B$5) -> 4588.1929
A18: Total Charges (PKR) | B18: =SUMIFS('Daily Summary'!$J$5:$J$404,'Daily Summary'!$A$5:$A$404,">="&$B$4,'Daily Summary'!$A$5:$A$404,"<="&$B$5) -> 39881.984
A19: Net P&L (PKR) | B19: =SUMIFS('Daily Summary'!$K$5:$K$404,'Daily Summary'!$A$5:$A$404,">="&$B$4,'Daily Summary'!$A$5:$A$404,"<="&$B$5) -> 39790.636
A20: Return on Buy | B20: =IF($B$13=0,"",$B$19/$B$13) -> 0.00035470732
A22: Date-by-Date Breakdown
A23: Date | B23: Buy Qty | C23: Sell Qty | D23: Net Qty | E23: Buy Value (PKR) | F23: Sell Value (PKR) | G23: Gross P&L (PKR) | H23: Commission (PKR) | I23: SST (PKR) | J23: Total Charges (PKR) | K23: Net P&L (PKR) | L23: Return on Buy
A24: ='Daily Summary'!A30 -> 46296 | B24: ='Daily Summary'!B30 -> 61500 | C24: ='Daily Summary'!C30 -> 61500 | D24: ='Daily Summary'!D30 -> 0 | E24: ='Daily Summary'!E30 -> 9592760 | F24: ='Daily Summary'!F30 -> 9603580 | G24: ='Daily Summary'!G30 -> 10820 | H24: ='Daily Summary'!H30 -> 3121.1635 | ... L24: ='Daily Summary'!L30 -> 0.00076026975
A25: ='Daily Summary'!A31 -> 46297 | B25: ='Daily Summary'!B31 -> 35500 | C25: ='Daily Summary'!C31 -> 35500 | D25: ='Daily Summary'!D31 -> 0 | E25: ='Daily Summary'!E31 -> 8710670 | F25: ='Daily Summary'!F31 -> 8714260 | G25: ='Daily Summary'!G31 -> 3590 | H25: ='Daily Summary'!H31 -> 2832.1345 | ... L25: ='Daily Summary'!L31 -> 4.4736859e-05
A26: ='Daily Summary'!A32 -> 46300 | B26: ='Daily Summary'!B32 -> 60000 | C26: ='Daily Summary'!C32 -> 60000 | D26: ='Daily Summary'!D32 -> 0 | E26: ='Daily Summary'!E32 -> 6890615 | F26: ='Daily Summary'!F32 -> 6893846.3 | G26: ='Daily Summary'!G32 -> 3231.33 | H26: ='Daily Summary'!H32 -> 2240.5001 | ... L26: ='Daily Summary'!L32 -> 0.00010152431
A27: ='Daily Summary'!A33 -> 46301 | B27: ='Daily Summary'!B33 -> 126235 | C27: ='Daily Summary'!C33 -> 126235 | D27: ='Daily Summary'!D33 -> 0 | E27: ='Daily Summary'!E33 -> 19094354 | F27: ='Daily Summary'!F33 -> 19099591 | G27: ='Daily Summary'!G33 -> 5237.26 | H27: ='Daily Summary'!H33 -> 5871.6662 | ... L27: ='Daily Summary'!L33 -> -7.3200846e-05
A28: ='Daily Summary'!A34 -> 46302 | B28: ='Daily Summary'!B34 -> 114400 | C28: ='Daily Summary'!C34 -> 114400 | D28: ='Daily Summary'!D34 -> 0 | E28: ='Daily Summary'!E34 -> 15990980 | F28: ='Daily Summary'!F34 -> 16004711 | G28: ='Daily Summary'!G34 -> 13730.84 | H28: ='Daily Summary'!H34 -> 5201.5311 | ... L28: ='Daily Summary'!L34 -> 0.00049109622
A29: ='Daily Summary'!A35 -> 46303 | B29: ='Daily Summary'!B35 -> 62859 | C29: ='Daily Summary'!C35 -> 62859 | D29: ='Daily Summary'!D35 -> 0 | E29: ='Daily Summary'!E35 -> 9701743.2 | F29: ='Daily Summary'!F35 -> 9715115.4 | G29: ='Daily Summary'!G35 -> 13372.19 | H29: ='Daily Summary'!H35 -> 3157.4125 | ... L29: ='Daily Summary'!L35 -> 0.0010105724
A30: ='Daily Summary'!A36 -> 46304 | B30: ='Daily Summary'!B36 -> 28000 | C30: ='Daily Summary'!C36 -> 28000 | D30: ='Daily Summary'!D36 -> 0 | E30: ='Daily Summary'!E36 -> 3975465 | F30: ='Daily Summary'!F36 -> 3982225 | G30: ='Daily Summary'!G36 -> 6760 | H30: ='Daily Summary'!H36 -> 1294.2231 | ... L30: ='Daily Summary'!L36 -> 0.0013325555
A31: ='Daily Summary'!A37 -> 46307 | B31: ='Daily Summary'!B37 -> 119500 | C31: ='Daily Summary'!C37 -> 119500 | D31: ='Daily Summary'!D37 -> 0 | E31: ='Daily Summary'!E37 -> 13087568 | F31: ='Daily Summary'!F37 -> 13093430 | G31: ='Daily Summary'!G37 -> 5862 | H31: ='Daily Summary'!H37 -> 4088.782 | ... L31: ='Daily Summary'!L37 -> 9.487449e-05
A32: ='Daily Summary'!A38 -> 46308 | B32: ='Daily Summary'!B38 -> 111000 | C32: ='Daily Summary'!C38 -> 111000 | D32: ='Daily Summary'!D38 -> 0 | E32: ='Daily Summary'!E38 -> 8618263 | F32: ='Daily Summary'!F38 -> 8617447 | G32: ='Daily Summary'!G38 -> -816 | H32: ='Daily Summary'!H38 -> 2112.7472 | ... L32: ='Daily Summary'!L38 -> -0.00037169953
A33: ='Daily Summary'!A39 -> 46310 | B33: ='Daily Summary'!B39 -> 72500 | C33: ='Daily Summary'!C39 -> 72500 | D33: ='Daily Summary'!D39 -> 0 | E33: ='Daily Summary'!E39 -> 11671305 | F33: ='Daily Summary'!F39 -> 11678640 | G33: ='Daily Summary'!G39 -> 7335 | H33: ='Daily Summary'!H39 -> 3795.558 | ... L33: ='Daily Summary'!L39 -> 0.00026098362
A34: ='Daily Summary'!A40 -> 46311 | B34: ='Daily Summary'!B40 -> 22500 | C34: ='Daily Summary'!C40 -> 22500 | D34: ='Daily Summary'!D40 -> 0 | E34: ='Daily Summary'!E40 -> 4845060 | F34: ='Daily Summary'!F40 -> 4855610 | G34: ='Daily Summary'!G40 -> 10550 | H34: ='Daily Summary'!H40 -> 1578.0732 | ... L34: ='Daily Summary'!L40 -> 0.0018094259
A35: TOTAL | B35: =SUM(B24:B34) -> 813994 | C35: =SUM(C24:C34) -> 813994 | D35: =$B35-$C35 -> 0 | E35: =SUM(E24:E34) -> 1.1217878e+08 | F35: =SUM(F24:F34) -> 1.1225846e+08 | G35: =SUM(G24:G34) -> 79672.62 | H35: =SUM(H24:H34) -> 35293.791 | I35: =SUM(I24:I34) -> 4588.1929 | J35: =SUM(J24:J34) -> 39881.984 | K35: =SUM(K24:K34) -> 39790.636 | L35: =IF($E35=0,"",$K35/$E35) -> 0.00035470732

Sheet QTD Summary
A1: Quarter-to-Date — Q4 2026 (Oct–Dec)
A2: Live SUMIFS over the Daily Summary, bounded by the period dates below.
A4: Period Start (calendar): | B4: 46296
A5: Period End (latest trade): | B5: =MAX('Daily Summary'!$A$5:$A$404) -> 46311
A6: First Trading Day in Period: | B6: =IFERROR(IF(INDEX('Daily Summary'!$A$5:$A$404,COUNTIF('Daily Summary'!$A$5:$A$404,"<"&$B$4)+1)>$B$5,"—",INDEX('Daily Summary'!$A$5:$A$404,COUNTIF('Daily Summary'!$A$5:$A$404,"<"&$B$4)+1)),"—") -> 46296
A7: Trading Days: | B7: =COUNTIFS('Daily Summary'!$A$5:$A$404,">="&$B$4,'Daily Summary'!$A$5:$A$404,"<="&$B$5) -> 11
A9: Metric | B9: Value
A10: Buy Quantity | B10: =SUMIFS('Daily Summary'!$B$5:$B$404,'Daily Summary'!$A$5:$A$404,">="&$B$4,'Daily Summary'!$A$5:$A$404,"<="&$B$5) -> 813994
A11: Sell Quantity | B11: =SUMIFS('Daily Summary'!$C$5:$C$404,'Daily Summary'!$A$5:$A$404,">="&$B$4,'Daily Summary'!$A$5:$A$404,"<="&$B$5) -> 813994
A12: Net Quantity | B12: =SUMIFS('Daily Summary'!$D$5:$D$404,'Daily Summary'!$A$5:$A$404,">="&$B$4,'Daily Summary'!$A$5:$A$404,"<="&$B$5) -> 0
A13: Buy Value (PKR) | B13: =SUMIFS('Daily Summary'!$E$5:$E$404,'Daily Summary'!$A$5:$A$404,">="&$B$4,'Daily Summary'!$A$5:$A$404,"<="&$B$5) -> 1.1217878e+08
A14: Sell Value (PKR) | B14: =SUMIFS('Daily Summary'!$F$5:$F$404,'Daily Summary'!$A$5:$A$404,">="&$B$4,'Daily Summary'!$A$5:$A$404,"<="&$B$5) -> 1.1225846e+08
A15: Gross P&L (PKR) | B15: =SUMIFS('Daily Summary'!$G$5:$G$404,'Daily Summary'!$A$5:$A$404,">="&$B$4,'Daily Summary'!$A$5:$A$404,"<="&$B$5) -> 79672.62
A16: Commission (PKR) | B16: =SUMIFS('Daily Summary'!$H$5:$H$404,'Daily Summary'!$A$5:$A$404,">="&$B$4,'Daily Summary'!$A$5:$A$404,"<="&$B$5) -> 35293.791
A17: SST (PKR) | B17: =SUMIFS('Daily Summary'!$I$5:$I$404,'Daily Summary'!$A$5:$A$404,">="&$B$4,'Daily Summary'!$A$5:$A$404,"<="&$B$5) -> 4588.1929
A18: Total Charges (PKR) | B18: =SUMIFS('Daily Summary'!$J$5:$J$404,'Daily Summary'!$A$5:$A$404,">="&$B$4,'Daily Summary'!$A$5:$A$404,"<="&$B$5) -> 39881.984
A19: Net P&L (PKR) | B19: =SUMIFS('Daily Summary'!$K$5:$K$404,'Daily Summary'!$A$5:$A$404,">="&$B$4,'Daily Summary'!$A$5:$A$404,"<="&$B$5) -> 39790.636
A20: Return on Buy | B20: =IF($B$13=0,"",$B$19/$B$13) -> 0.00035470732
A22: Date-by-Date Breakdown
A23: Date | B23: Buy Qty | C23: Sell Qty | D23: Net Qty | E23: Buy Value (PKR) | F23: Sell Value (PKR) | G23: Gross P&L (PKR) | H23: Commission (PKR) | I23: SST (PKR) | J23: Total Charges (PKR) | K23: Net P&L (PKR) | L23: Return on Buy
A24: ='Daily Summary'!A30 -> 46296 | B24: ='Daily Summary'!B30 -> 61500 | C24: ='Daily Summary'!C30 -> 61500 | D24: ='Daily Summary'!D30 -> 0 | E24: ='Daily Summary'!E30 -> 9592760 | F24: ='Daily Summary'!F30 -> 9603580 | G24: ='Daily Summary'!G30 -> 10820 | H24: ='Daily Summary'!H30 -> 3121.1635 | ... L24: ='Daily Summary'!L30 -> 0.00076026975
A25: ='Daily Summary'!A31 -> 46297 | B25: ='Daily Summary'!B31 -> 35500 | C25: ='Daily Summary'!C31 -> 35500 | D25: ='Daily Summary'!D31 -> 0 | E25: ='Daily Summary'!E31 -> 8710670 | F25: ='Daily Summary'!F31 -> 8714260 | G25: ='Daily Summary'!G31 -> 3590 | H25: ='Daily Summary'!H31 -> 2832.1345 | ... L25: ='Daily Summary'!L31 -> 4.4736859e-05
A26: ='Daily Summary'!A32 -> 46300 | B26: ='Daily Summary'!B32 -> 60000 | C26: ='Daily Summary'!C32 -> 60000 | D26: ='Daily Summary'!D32 -> 0 | E26: ='Daily Summary'!E32 -> 6890615 | F26: ='Daily Summary'!F32 -> 6893846.3 | G26: ='Daily Summary'!G32 -> 3231.33 | H26: ='Daily Summary'!H32 -> 2240.5001 | ... L26: ='Daily Summary'!L32 -> 0.00010152431
A27: ='Daily Summary'!A33 -> 46301 | B27: ='Daily Summary'!B33 -> 126235 | C27: ='Daily Summary'!C33 -> 126235 | D27: ='Daily Summary'!D33 -> 0 | E27: ='Daily Summary'!E33 -> 19094354 | F27: ='Daily Summary'!F33 -> 19099591 | G27: ='Daily Summary'!G33 -> 5237.26 | H27: ='Daily Summary'!H33 -> 5871.6662 | ... L27: ='Daily Summary'!L33 -> -7.3200846e-05
A28: ='Daily Summary'!A34 -> 46302 | B28: ='Daily Summary'!B34 -> 114400 | C28: ='Daily Summary'!C34 -> 114400 | D28: ='Daily Summary'!D34 -> 0 | E28: ='Daily Summary'!E34 -> 15990980 | F28: ='Daily Summary'!F34 -> 16004711 | G28: ='Daily Summary'!G34 -> 13730.84 | H28: ='Daily Summary'!H34 -> 5201.5311 | ... L28: ='Daily Summary'!L34 -> 0.00049109622
A29: ='Daily Summary'!A35 -> 46303 | B29: ='Daily Summary'!B35 -> 62859 | C29: ='Daily Summary'!C35 -> 62859 | D29: ='Daily Summary'!D35 -> 0 | E29: ='Daily Summary'!E35 -> 9701743.2 | F29: ='Daily Summary'!F35 -> 9715115.4 | G29: ='Daily Summary'!G35 -> 13372.19 | H29: ='Daily Summary'!H35 -> 3157.4125 | ... L29: ='Daily Summary'!L35 -> 0.0010105724
A30: ='Daily Summary'!A36 -> 46304 | B30: ='Daily Summary'!B36 -> 28000 | C30: ='Daily Summary'!C36 -> 28000 | D30: ='Daily Summary'!D36 -> 0 | E30: ='Daily Summary'!E36 -> 3975465 | F30: ='Daily Summary'!F36 -> 3982225 | G30: ='Daily Summary'!G36 -> 6760 | H30: ='Daily Summary'!H36 -> 1294.2231 | ... L30: ='Daily Summary'!L36 -> 0.0013325555
A31: ='Daily Summary'!A37 -> 46307 | B31: ='Daily Summary'!B37 -> 119500 | C31: ='Daily Summary'!C37 -> 119500 | D31: ='Daily Summary'!D37 -> 0 | E31: ='Daily Summary'!E37 -> 13087568 | F31: ='Daily Summary'!F37 -> 13093430 | G31: ='Daily Summary'!G37 -> 5862 | H31: ='Daily Summary'!H37 -> 4088.782 | ... L31: ='Daily Summary'!L37 -> 9.487449e-05
A32: ='Daily Summary'!A38 -> 46308 | B32: ='Daily Summary'!B38 -> 111000 | C32: ='Daily Summary'!C38 -> 111000 | D32: ='Daily Summary'!D38 -> 0 | E32: ='Daily Summary'!E38 -> 8618263 | F32: ='Daily Summary'!F38 -> 8617447 | G32: ='Daily Summary'!G38 -> -816 | H32: ='Daily Summary'!H38 -> 2112.7472 | ... L32: ='Daily Summary'!L38 -> -0.00037169953
A33: ='Daily Summary'!A39 -> 46310 | B33: ='Daily Summary'!B39 -> 72500 | C33: ='Daily Summary'!C39 -> 72500 | D33: ='Daily Summary'!D39 -> 0 | E33: ='Daily Summary'!E39 -> 11671305 | F33: ='Daily Summary'!F39 -> 11678640 | G33: ='Daily Summary'!G39 -> 7335 | H33: ='Daily Summary'!H39 -> 3795.558 | ... L33: ='Daily Summary'!L39 -> 0.00026098362
A34: ='Daily Summary'!A40 -> 46311 | B34: ='Daily Summary'!B40 -> 22500 | C34: ='Daily Summary'!C40 -> 22500 | D34: ='Daily Summary'!D40 -> 0 | E34: ='Daily Summary'!E40 -> 4845060 | F34: ='Daily Summary'!F40 -> 4855610 | G34: ='Daily Summary'!G40 -> 10550 | H34: ='Daily Summary'!H40 -> 1578.0732 | ... L34: ='Daily Summary'!L40 -> 0.0018094259
A35: TOTAL | B35: =SUM(B24:B34) -> 813994 | C35: =SUM(C24:C34) -> 813994 | D35: =$B35-$C35 -> 0 | E35: =SUM(E24:E34) -> 1.1217878e+08 | F35: =SUM(F24:F34) -> 1.1225846e+08 | G35: =SUM(G24:G34) -> 79672.62 | H35: =SUM(H24:H34) -> 35293.791 | I35: =SUM(I24:I34) -> 4588.1929 | J35: =SUM(J24:J34) -> 39881.984 | K35: =SUM(K24:K34) -> 39790.636 | L35: =IF($E35=0,"",$K35/$E35) -> 0.00035470732

Sheet YTD Summary
A1: Year-to-Date — 2026
A2: Live SUMIFS over the Daily Summary, bounded by the period dates below.
A4: Period Start (calendar): | B4: 46023
A5: Period End (latest trade): | B5: =MAX('Daily Summary'!$A$5:$A$404) -> 46311
A6: First Trading Day in Period: | B6: =IFERROR(IF(INDEX('Daily Summary'!$A$5:$A$404,COUNTIF('Daily Summary'!$A$5:$A$404,"<"&$B$4)+1)>$B$5,"—",INDEX('Daily Summary'!$A$5:$A$404,COUNTIF('Daily Summary'!$A$5:$A$404,"<"&$B$4)+1)),"—") -> 46251
A7: Trading Days: | B7: =COUNTIFS('Daily Summary'!$A$5:$A$404,">="&$B$4,'Daily Summary'!$A$5:$A$404,"<="&$B$5) -> 36
A9: Metric | B9: Value
A10: Buy Quantity | B10: =SUMIFS('Daily Summary'!$B$5:$B$404,'Daily Summary'!$A$5:$A$404,">="&$B$4,'Daily Summary'!$A$5:$A$404,"<="&$B$5) -> 2612821
A11: Sell Quantity | B11: =SUMIFS('Daily Summary'!$C$5:$C$404,'Daily Summary'!$A$5:$A$404,">="&$B$4,'Daily Summary'!$A$5:$A$404,"<="&$B$5) -> 2612821
A12: Net Quantity | B12: =SUMIFS('Daily Summary'!$D$5:$D$404,'Daily Summary'!$A$5:$A$404,">="&$B$4,'Daily Summary'!$A$5:$A$404,"<="&$B$5) -> 0
A13: Buy Value (PKR) | B13: =SUMIFS('Daily Summary'!$E$5:$E$404,'Daily Summary'!$A$5:$A$404,">="&$B$4,'Daily Summary'!$A$5:$A$404,"<="&$B$5) -> 4.0323137e+08
A14: Sell Value (PKR) | B14: =SUMIFS('Daily Summary'!$F$5:$F$404,'Daily Summary'!$A$5:$A$404,">="&$B$4,'Daily Summary'!$A$5:$A$404,"<="&$B$5) -> 4.0357074e+08
A15: Gross P&L (PKR) | B15: =SUMIFS('Daily Summary'!$G$5:$G$404,'Daily Summary'!$A$5:$A$404,">="&$B$4,'Daily Summary'!$A$5:$A$404,"<="&$B$5) -> 339374.14
A16: Commission (PKR) | B16: =SUMIFS('Daily Summary'!$H$5:$H$404,'Daily Summary'!$A$5:$A$404,">="&$B$4,'Daily Summary'!$A$5:$A$404,"<="&$B$5) -> 129301.35
A17: SST (PKR) | B17: =SUMIFS('Daily Summary'!$I$5:$I$404,'Daily Summary'!$A$5:$A$404,">="&$B$4,'Daily Summary'!$A$5:$A$404,"<="&$B$5) -> 16809.176
A18: Total Charges (PKR) | B18: =SUMIFS('Daily Summary'!$J$5:$J$404,'Daily Summary'!$A$5:$A$404,">="&$B$4,'Daily Summary'!$A$5:$A$404,"<="&$B$5) -> 146110.53
A19: Net P&L (PKR) | B19: =SUMIFS('Daily Summary'!$K$5:$K$404,'Daily Summary'!$A$5:$A$404,">="&$B$4,'Daily Summary'!$A$5:$A$404,"<="&$B$5) -> 193263.61
A20: Return on Buy | B20: =IF($B$13=0,"",$B$19/$B$13) -> 0.00047928714
A22: Date-by-Date Breakdown
A23: Date | B23: Buy Qty | C23: Sell Qty | D23: Net Qty | E23: Buy Value (PKR) | F23: Sell Value (PKR) | G23: Gross P&L (PKR) | H23: Commission (PKR) | I23: SST (PKR) | J23: Total Charges (PKR) | K23: Net P&L (PKR) | L23: Return on Buy
A24: ='Daily Summary'!A5 -> 46251 | B24: ='Daily Summary'!B5 -> 70500 | C24: ='Daily Summary'!C5 -> 70500 | D24: ='Daily Summary'!D5 -> 0 | E24: ='Daily Summary'!E5 -> 18267720 | F24: ='Daily Summary'!F5 -> 18287930 | G24: ='Daily Summary'!G5 -> 20210 | H24: ='Daily Summary'!H5 -> 5943.5773 | ... L24: ='Daily Summary'!L5 -> 0.00073866677
A25: ='Daily Summary'!A6 -> 46252 | B25: ='Daily Summary'!B6 -> 125640 | C25: ='Daily Summary'!C6 -> 125640 | D25: ='Daily Summary'!D6 -> 0 | E25: ='Daily Summary'!E6 -> 21984905 | F25: ='Daily Summary'!F6 -> 22001335 | G25: ='Daily Summary'!G6 -> 16430 | H25: ='Daily Summary'!H6 -> 6920.3714 | ... L25: ='Daily Summary'!L6 -> 0.00039163146
A26: ='Daily Summary'!A7 -> 46253 | B26: ='Daily Summary'!B7 -> 96000 | C26: ='Daily Summary'!C7 -> 96000 | D26: ='Daily Summary'!D7 -> 0 | E26: ='Daily Summary'!E7 -> 12039745 | F26: ='Daily Summary'!F7 -> 12062720 | G26: ='Daily Summary'!G7 -> 22975 | H26: ='Daily Summary'!H7 -> 3851.2528 | ... L26: ='Daily Summary'!L7 -> 0.0015468006
A27: ='Daily Summary'!A8 -> 46254 | B27: ='Daily Summary'!B8 -> 63500 | C27: ='Daily Summary'!C8 -> 63500 | D27: ='Daily Summary'!D8 -> 0 | E27: ='Daily Summary'!E8 -> 10062968 | F27: ='Daily Summary'!F8 -> 10084865 | G27: ='Daily Summary'!G8 -> 21896.51 | H27: ='Daily Summary'!H8 -> 3277.581 | ... L27: ='Daily Summary'!L8 -> 0.0018079004
A28: ='Daily Summary'!A9 -> 46255 | B28: ='Daily Summary'!B9 -> 45357 | C28: ='Daily Summary'!C9 -> 45357 | D28: ='Daily Summary'!D9 -> 0 | E28: ='Daily Summary'!E9 -> 8763520 | F28: ='Daily Summary'!F9 -> 8772484.3 | G28: ='Daily Summary'!G9 -> 8964.29 | H28: ='Daily Summary'!H9 -> 2851.0574 | ... L28: ='Daily Summary'!L9 -> 0.00065528408
A29: ='Daily Summary'!A10 -> 46258 | B29: ='Daily Summary'!B10 -> 84004 | C29: ='Daily Summary'!C10 -> 84004 | D29: ='Daily Summary'!D10 -> 0 | E29: ='Daily Summary'!E10 -> 13130113 | F29: ='Daily Summary'!F10 -> 13155567 | G29: ='Daily Summary'!G10 -> 25454.29 | H29: ='Daily Summary'!H10 -> 4275.5592 | ... L29: ='Daily Summary'!L10 -> 0.0015706574
A30: ='Daily Summary'!A11 -> 46261 | B30: ='Daily Summary'!B11 -> 26500 | C30: ='Daily Summary'!C11 -> 26500 | D30: ='Daily Summary'!D11 -> 0 | E30: ='Daily Summary'!E11 -> 2407645 | F30: ='Daily Summary'!F11 -> 2404525 | G30: ='Daily Summary'!G11 -> -3120 | H30: ='Daily Summary'!H11 -> 781.47063 | ... L30: ='Daily Summary'!L11 -> -0.0016626462
A31: ='Daily Summary'!A12 -> 46265 | B31: ='Daily Summary'!B12 -> 51500 | C31: ='Daily Summary'!C12 -> 51500 | D31: ='Daily Summary'!D12 -> 0 | E31: ='Daily Summary'!E12 -> 18280837 | F31: ='Daily Summary'!F12 -> 18292560 | G31: ='Daily Summary'!G12 -> 11723.11 | H31: ='Daily Summary'!H12 -> 5945.082 | ... L31: ='Daily Summary'!L12 -> 0.00027379312
A32: ='Daily Summary'!A13 -> 46266 | B32: ='Daily Summary'!B13 -> 40920 | C32: ='Daily Summary'!C13 -> 40920 | D32: ='Daily Summary'!D13 -> 0 | E32: ='Daily Summary'!E13 -> 13686449 | F32: ='Daily Summary'!F13 -> 13711864 | G32: ='Daily Summary'!G13 -> 25415.3 | H32: ='Daily Summary'!H13 -> 4456.3559 | ... L32: ='Daily Summary'!L13 -> 0.0014890362
A33: ='Daily Summary'!A14 -> 46267 | B33: ='Daily Summary'!B14 -> 115000 | C33: ='Daily Summary'!C14 -> 115000 | D33: ='Daily Summary'!D14 -> 0 | E33: ='Daily Summary'!E14 -> 14853375 | F33: ='Daily Summary'!F14 -> 14863825 | G33: ='Daily Summary'!G14 -> 10450.36 | H33: ='Daily Summary'!H14 -> 4830.7432 | ... L33: ='Daily Summary'!L14 -> 0.00033605966
A34: ='Daily Summary'!A15 -> 46268 | B34: ='Daily Summary'!B15 -> 85000 | C34: ='Daily Summary'!C15 -> 85000 | D34: ='Daily Summary'!D15 -> 0 | E34: ='Daily Summary'!E15 -> 15859132 | F34: ='Daily Summary'!F15 -> 15867402 | G34: ='Daily Summary'!G15 -> 8269.59 | H34: ='Daily Summary'!H15 -> 5156.9056 | ... L34: ='Daily Summary'!L15 -> 0.00015399876
A35: ='Daily Summary'!A16 -> 46269 | B35: ='Daily Summary'!B16 -> 139200 | C35: ='Daily Summary'!C16 -> 139200 | D35: ='Daily Summary'!D16 -> 0 | E35: ='Daily Summary'!E16 -> 22870427 | F35: ='Daily Summary'!F16 -> 22877215 | G35: ='Daily Summary'!G16 -> 6788.43 | H35: ='Daily Summary'!H16 -> 7435.0949 | ... L35: ='Daily Summary'!L16 -> -7.0537697e-05
... A59: ='Daily Summary'!A40 -> 46311 | B59: ='Daily Summary'!B40 -> 22500 | C59: ='Daily Summary'!C40 -> 22500 | D59: ='Daily Summary'!D40 -> 0 | E59: ='Daily Summary'!E40 -> 4845060 | F59: ='Daily Summary'!F40 -> 4855610 | G59: ='Daily Summary'!G40 -> 10550 | H59: ='Daily Summary'!H40 -> 1578.0732 | ... L59: ='Daily Summary'!L40 -> 0.0018094259
A60: TOTAL | B60: =SUM(B24:B59) -> 2612821 | C60: =SUM(C24:C59) -> 2612821 | D60: =$B60-$C60 -> 0 | E60: =SUM(E24:E59) -> 4.0323137e+08 | F60: =SUM(F24:F59) -> 4.0357074e+08 | G60: =SUM(G24:G59) -> 339374.14 | H60: =SUM(H24:H59) -> 129301.35 | I60: =SUM(I24:I59) -> 16809.176 | J60: =SUM(J24:J59) -> 146110.53 | K60: =SUM(K24:K59) -> 193263.61 | L60: =IF($E60=0,"",$K60/$E60) -> 0.00047928714

Sheet Monthly Summary
A1: Monthly Summary — Month-Wise Performance
A2: One row per calendar month with trading data, oldest → newest. Live SUMIFS over the Daily Summary.
A4: Month | B4: Buy Qty | C4: Buy Value (PKR) | D4: Avg Buy Price | E4: Sell Qty | F4: Sell Value (PKR) | G4: Avg Sell Price | H4: Price Diff (Sell−Buy) | I4: Net Qty | J4: Gross P&L (PKR) | K4: Commission Rate (Slab) | L4: Commission (PKR) | M4: SST 13% (PKR) | N4: Total Charges (PKR) | O4: Net P&L (PKR) | P4: Return on Buy
A5: 46235 | B5: =SUMIFS('Daily Summary'!$B$5:$B$404,'Daily Summary'!$A$5:$A$404,">="&$A5,'Daily Summary'!$A$5:$A$404,"<"&DATE(YEAR($A5),MONTH($A5)+1,1)) -> 563001 | C5: =SUMIFS('Daily Summary'!$E$5:$E$404,'Daily Summary'!$A$5:$A$404,">="&$A5,'Daily Summary'!$A$5:$A$404,"<"&DATE(YEAR($A5),MONTH($A5)+1,1)) -> 1.0493745e+08 | D5: =IF($B5=0,"",$C5/$B5) -> 186.38946 | E5: =SUMIFS('Daily Summary'!$C$5:$C$404,'Daily Summary'!$A$5:$A$404,">="&$A5,'Daily Summary'!$A$5:$A$404,"<"&DATE(YEAR($A5),MONTH($A5)+1,1)) -> 563001 | F5: =SUMIFS('Daily Summary'!$F$5:$F$404,'Daily Summary'!$A$5:$A$404,">="&$A5,'Daily Summary'!$A$5:$A$404,"<"&DATE(YEAR($A5),MONTH($A5)+1,1)) -> 1.0506199e+08 | G5: =IF($E5=0,"",$F5/$E5) -> 186.61066 | H5: =IF(OR($B5=0,$E5=0),"N/A",$G5-$D5) -> 0.22119534 | I5: =$B5-$E5 -> 0 | J5: =SUMIFS('Daily Summary'!$G$5:$G$404,'Daily Summary'!$A$5:$A$404,">="&$A5,'Daily Summary'!$A$5:$A$404,"<"&DATE(YEAR($A5),MONTH($A5)+1,1)) -> 124533.2 | K5: =IF($E5=0,"—",IF($G5>=Comm_Slab2_Start,"0.0325% of sell value","0.0175 paisa per share")) -> 0.0325% of sell value | L5: =SUMIFS('Daily Summary'!$H$5:$H$404,'Daily Summary'!$A$5:$A$404,">="&$A5,'Daily Summary'!$A$5:$A$404,"<"&DATE(YEAR($A5),MONTH($A5)+1,1)) -> 33845.952 | M5: =SUMIFS('Daily Summary'!$I$5:$I$404,'Daily Summary'!$A$5:$A$404,">="&$A5,'Daily Summary'!$A$5:$A$404,"<"&DATE(YEAR($A5),MONTH($A5)+1,1)) -> 4399.9737 | N5: =$L5+$M5 -> 38245.925 | O5: =SUMIFS('Daily Summary'!$K$5:$K$404,'Daily Summary'!$A$5:$A$404,">="&$A5,'Daily Summary'!$A$5:$A$404,"<"&DATE(YEAR($A5),MONTH($A5)+1,1)) -> 86287.275 | P5: =IF($C5=0,"N/A",$O5/$C5) -> 0.00082227339
A6: 46266 | B6: =SUMIFS('Daily Summary'!$B$5:$B$404,'Daily Summary'!$A$5:$A$404,">="&$A6,'Daily Summary'!$A$5:$A$404,"<"&DATE(YEAR($A6),MONTH($A6)+1,1)) -> 1235826 | C6: =SUMIFS('Daily Summary'!$E$5:$E$404,'Daily Summary'!$A$5:$A$404,">="&$A6,'Daily Summary'!$A$5:$A$404,"<"&DATE(YEAR($A6),MONTH($A6)+1,1)) -> 1.8611513e+08 | D6: =IF($B6=0,"",$C6/$B6) -> 150.59979 | E6: =SUMIFS('Daily Summary'!$C$5:$C$404,'Daily Summary'!$A$5:$A$404,">="&$A6,'Daily Summary'!$A$5:$A$404,"<"&DATE(YEAR($A6),MONTH($A6)+1,1)) -> 1235826 | F6: =SUMIFS('Daily Summary'!$F$5:$F$404,'Daily Summary'!$A$5:$A$404,">="&$A6,'Daily Summary'!$A$5:$A$404,"<"&DATE(YEAR($A6),MONTH($A6)+1,1)) -> 1.862503e+08 | G6: =IF($E6=0,"",$F6/$E6) -> 150.70916 | H6: =IF(OR($B6=0,$E6=0),"N/A",$G6-$D6) -> 0.10937488 | I6: =$B6-$E6 -> 0 | J6: =SUMIFS('Daily Summary'!$G$5:$G$404,'Daily Summary'!$A$5:$A$404,">="&$A6,'Daily Summary'!$A$5:$A$404,"<"&DATE(YEAR($A6),MONTH($A6)+1,1)) -> 135168.32 | K6: =IF($E6=0,"—",IF($G6>=Comm_Slab2_Start,"0.0325% of sell value","0.0175 paisa per share")) -> 0.0325% of sell value | L6: =SUMIFS('Daily Summary'!$H$5:$H$404,'Daily Summary'!$A$5:$A$404,">="&$A6,'Daily Summary'!$A$5:$A$404,"<"&DATE(YEAR($A6),MONTH($A6)+1,1)) -> 60161.61 | M6: =SUMIFS('Daily Summary'!$I$5:$I$404,'Daily Summary'!$A$5:$A$404,">="&$A6,'Daily Summary'!$A$5:$A$404,"<"&DATE(YEAR($A6),MONTH($A6)+1,1)) -> 7821.0093 | N6: =$L6+$M6 -> 67982.62 | O6: =SUMIFS('Daily Summary'!$K$5:$K$404,'Daily Summary'!$A$5:$A$404,">="&$A6,'Daily Summary'!$A$5:$A$404,"<"&DATE(YEAR($A6),MONTH($A6)+1,1)) -> 67185.7 | P6: =IF($C6=0,"N/A",$O6/$C6) -> 0.00036098999
A7: 46296 | B7: =SUMIFS('Daily Summary'!$B$5:$B$404,'Daily Summary'!$A$5:$A$404,">="&$A7,'Daily Summary'!$A$5:$A$404,"<"&DATE(YEAR($A7),MONTH($A7)+1,1)) -> 813994 | C7: =SUMIFS('Daily Summary'!$E$5:$E$404,'Daily Summary'!$A$5:$A$404,">="&$A7,'Daily Summary'!$A$5:$A$404,"<"&DATE(YEAR($A7),MONTH($A7)+1,1)) -> 1.1217878e+08 | D7: =IF($B7=0,"",$C7/$B7) -> 137.81279 | E7: =SUMIFS('Daily Summary'!$C$5:$C$404,'Daily Summary'!$A$5:$A$404,">="&$A7,'Daily Summary'!$A$5:$A$404,"<"&DATE(YEAR($A7),MONTH($A7)+1,1)) -> 813994 | F7: =SUMIFS('Daily Summary'!$F$5:$F$404,'Daily Summary'!$A$5:$A$404,">="&$A7,'Daily Summary'!$A$5:$A$404,"<"&DATE(YEAR($A7),MONTH($A7)+1,1)) -> 1.1225846e+08 | G7: =IF($E7=0,"",$F7/$E7) -> 137.91067 | H7: =IF(OR($B7=0,$E7=0),"N/A",$G7-$D7) -> 0.097878633 | I7: =$B7-$E7 -> 0 | J7: =SUMIFS('Daily Summary'!$G$5:$G$404,'Daily Summary'!$A$5:$A$404,">="&$A7,'Daily Summary'!$A$5:$A$404,"<"&DATE(YEAR($A7),MONTH($A7)+1,1)) -> 79672.62 | K7: =IF($E7=0,"—",IF($G7>=Comm_Slab2_Start,"0.0325% of sell value","0.0175 paisa per share")) -> 0.0325% of sell value | L7: =SUMIFS('Daily Summary'!$H$5:$H$404,'Daily Summary'!$A$5:$A$404,">="&$A7,'Daily Summary'!$A$5:$A$404,"<"&DATE(YEAR($A7),MONTH($A7)+1,1)) -> 35293.791 | M7: =SUMIFS('Daily Summary'!$I$5:$I$404,'Daily Summary'!$A$5:$A$404,">="&$A7,'Daily Summary'!$A$5:$A$404,"<"&DATE(YEAR($A7),MONTH($A7)+1,1)) -> 4588.1929 | N7: =$L7+$M7 -> 39881.984 | O7: =SUMIFS('Daily Summary'!$K$5:$K$404,'Daily Summary'!$A$5:$A$404,">="&$A7,'Daily Summary'!$A$5:$A$404,"<"&DATE(YEAR($A7),MONTH($A7)+1,1)) -> 39790.636 | P7: =IF($C7=0,"N/A",$O7/$C7) -> 0.00035470732
A8: TOTAL | B8: =SUM(B5:B7) -> 2612821 | C8: =SUM(C5:C7) -> 4.0323137e+08 | D8: =IF($B8=0,"",$C8/$B8) -> 154.32797 | E8: =SUM(E5:E7) -> 2612821 | F8: =SUM(F5:F7) -> 4.0357074e+08 | G8: =IF($E8=0,"",$F8/$E8) -> 154.45786 | H8: =IF(OR($B8=0,$E8=0),"N/A",$G8-$D8) -> 0.12988802 | I8: =$B8-$E8 -> 0 | J8: =SUM(J5:J7) -> 339374.14 | L8: =SUM(L5:L7) -> 129301.35 | M8: =SUM(M5:M7) -> 16809.176 | N8: =$L8+$M8 -> 146110.53 | O8: =SUM(O5:O7) -> 193263.61 | P8: =IF($C8=0,"N/A",$O8/$C8) -> 0.00047928714
A10: Note: all figures accumulate the underlying execution history for the whole period (weighted averages from totals; Return on Buy = Net P&L ÷ Buy Value, never averaged). Commission is accumulated per execution; the slab label reflects the period's weighted-average sell rate.

Sheet Yearly Summary
A1: Yearly Summary — Year-Wise Performance
A2: One row per calendar year with trading data, oldest → newest. Live SUMIFS over the Daily Summary.
A4: Year | B4: Buy Qty | C4: Buy Value (PKR) | D4: Avg Buy Price | E4: Sell Qty | F4: Sell Value (PKR) | G4: Avg Sell Price | H4: Price Diff (Sell−Buy) | I4: Net Qty | J4: Gross P&L (PKR) | K4: Commission Rate (Slab) | L4: Commission (PKR) | M4: SST 13% (PKR) | N4: Total Charges (PKR) | O4: Net P&L (PKR) | P4: Return on Buy
A5: 2026 | B5: =SUMIFS('Daily Summary'!$B$5:$B$404,'Daily Summary'!$A$5:$A$404,">="&$A5,'Daily Summary'!$A$5:$A$404,"<"&DATE($A5+1,1,1)) -> 2612821 | C5: =SUMIFS('Daily Summary'!$E$5:$E$404,'Daily Summary'!$A$5:$A$404,">="&$A5,'Daily Summary'!$A$5:$A$404,"<"&DATE($A5+1,1,1)) -> 4.0323137e+08 | D5: =IF($B5=0,"",$C5/$B5) -> 154.32797 | E5: =SUMIFS('Daily Summary'!$C$5:$C$404,'Daily Summary'!$A$5:$A$404,">="&$A5,'Daily Summary'!$A$5:$A$404,"<"&DATE($A5+1,1,1)) -> 2612821 | F5: =SUMIFS('Daily Summary'!$F$5:$F$404,'Daily Summary'!$A$5:$A$404,">="&$A5,'Daily Summary'!$A$5:$A$404,"<"&DATE($A5+1,1,1)) -> 4.0357074e+08 | G5: =IF($E5=0,"",$F5/$E5) -> 154.45786 | H5: =IF(OR($B5=0,$E5=0),"N/A",$G5-$D5) -> 0.12988802 | I5: =$B5-$E5 -> 0 | J5: =SUMIFS('Daily Summary'!$G$5:$G$404,'Daily Summary'!$A$5:$A$404,">="&$A5,'Daily Summary'!$A$5:$A$404,"<"&DATE($A5+1,1,1)) -> 339374.14 | K5: =IF($E5=0,"—",IF($G5>=Comm_Slab2_Start,"0.0325% of sell value","0.0175 paisa per share")) -> 0.0325% of sell value | L5: =SUMIFS('Daily Summary'!$H$5:$H$404,'Daily Summary'!$A$5:$A$404,">="&$A5,'Daily Summary'!$A$5:$A$404,"<"&DATE($A5+1,1,1)) -> 129301.35 | M5: =SUMIFS('Daily Summary'!$I$5:$I$404,'Daily Summary'!$A$5:$A$404,">="&$A5,'Daily Summary'!$A$5:$A$404,"<"&DATE($A5+1,1,1)) -> 16809.176 | N5: =$L5+$M5 -> 146110.53 | O5: =SUMIFS('Daily Summary'!$K$5:$K$404,'Daily Summary'!$A$5:$A$404,">="&$A5,'Daily Summary'!$A$5:$A$404,"<"&DATE($A5+1,1,1)) -> 193263.61 | P5: =IF($C5=0,"N/A",$O5/$C5) -> 0.00047928714
A6: TOTAL | B6: =SUM(B5) -> 2612821 | C6: =SUM(C5) -> 4.0323137e+08 | D6: =IF($B6=0,"",$C6/$B6) -> 154.32797 | E6: =SUM(E5) -> 2612821 | F6: =SUM(F5) -> 4.0357074e+08 | G6: =IF($E6=0,"",$F6/$E6) -> 154.45786 | H6: =IF(OR($B6=0,$E6=0),"N/A",$G6-$D6) -> 0.12988802 | I6: =$B6-$E6 -> 0 | J6: =SUM(J5) -> 339374.14 | L6: =SUM(L5) -> 129301.35 | M6: =SUM(M5) -> 16809.176 | N6: =$L6+$M6 -> 146110.53 | O6: =SUM(O5) -> 193263.61 | P6: =IF($C6=0,"N/A",$O6/$C6) -> 0.00047928714
A8: Note: all figures accumulate the underlying execution history for the whole period (weighted averages from totals; Return on Buy = Net P&L ÷ Buy Value, never averaged). Commission is accumulated per execution; the slab label reflects the period's weighted-average sell rate.

Sheet Symbol Performance
A1: Symbol Performance — All Trading Dates
A2: Aggregated across the full imported history (live SUMIF over the Daily Trade Summary), sorted by Net P&L.
A4: Symbol | B4: Buy Qty | C4: Sell Qty | D4: Buy Value (PKR) | E4: Sell Value (PKR) | F4: Gross P&L (PKR) | G4: Commission (PKR) | H4: SST (PKR) | I4: Net P&L (PKR) | J4: Return on Buy
A5: PRL-AUG | B5: =SUMIF('Daily Trade Summary'!$A:$A,$A5,'Daily Trade Summary'!$B:$B) -> 212500 | C5: =SUMIF('Daily Trade Summary'!$A:$A,$A5,'Daily Trade Summary'!$E:$E) -> 212500 | D5: =SUMIF('Daily Trade Summary'!$A:$A,$A5,'Daily Trade Summary'!$C:$C) -> 17760910 | E5: =SUMIF('Daily Trade Summary'!$A:$A,$A5,'Daily Trade Summary'!$F:$F) -> 17805100 | F5: =$E5-$D5 -> 44190 | G5: =SUMIF('Daily Trade Summary'!$A:$A,$A5,'Daily Trade Summary'!$L:$L) -> 5786.6575 | H5: =$G5*SST_Rate -> 752.26548 | I5: =$F5-$G5-$H5 -> 37651.077 | J5: =IF($D5=0,"N/A",$I5/$D5) -> 0.0021198845 | K5: ◄ Best performer
A6: PRL-SEP | B6: =SUMIF('Daily Trade Summary'!$A:$A,$A6,'Daily Trade Summary'!$B:$B) -> 494000 | C6: =SUMIF('Daily Trade Summary'!$A:$A,$A6,'Daily Trade Summary'!$E:$E) -> 494000 | D6: =SUMIF('Daily Trade Summary'!$A:$A,$A6,'Daily Trade Summary'!$C:$C) -> 47581770 | E6: =SUMIF('Daily Trade Summary'!$A:$A,$A6,'Daily Trade Summary'!$F:$F) -> 47630070 | F6: =$E6-$D6 -> 48300 | G6: =SUMIF('Daily Trade Summary'!$A:$A,$A6,'Daily Trade Summary'!$L:$L) -> 15479.773 | H6: =$G6*SST_Rate -> 2012.3705 | I6: =$F6-$G6-$H6 -> 30807.857 | J6: =IF($D6=0,"N/A",$I6/$D6) -> 0.00064747185
A7: PRL | B7: =SUMIF('Daily Trade Summary'!$A:$A,$A7,'Daily Trade Summary'!$B:$B) -> 187050 | C7: =SUMIF('Daily Trade Summary'!$A:$A,$A7,'Daily Trade Summary'!$E:$E) -> 187050 | D7: =SUMIF('Daily Trade Summary'!$A:$A,$A7,'Daily Trade Summary'!$C:$C) -> 17706341 | E7: =SUMIF('Daily Trade Summary'!$A:$A,$A7,'Daily Trade Summary'!$F:$F) -> 17737430 | F7: =$E7-$D7 -> 31088.98 | G7: =SUMIF('Daily Trade Summary'!$A:$A,$A7,'Daily Trade Summary'!$L:$L) -> 5764.6647 | H7: =$G7*SST_Rate -> 749.40641 | I7: =$F7-$G7-$H7 -> 24574.909 | J7: =IF($D7=0,"N/A",$I7/$D7) -> 0.0013879157
A8: NRL-AUG | B8: =SUMIF('Daily Trade Summary'!$A:$A,$A8,'Daily Trade Summary'!$B:$B) -> 31000 | C8: =SUMIF('Daily Trade Summary'!$A:$A,$A8,'Daily Trade Summary'!$E:$E) -> 31000 | D8: =SUMIF('Daily Trade Summary'!$A:$A,$A8,'Daily Trade Summary'!$C:$C) -> 16071720 | E8: =SUMIF('Daily Trade Summary'!$A:$A,$A8,'Daily Trade Summary'!$F:$F) -> 16091315 | F8: =$E8-$D8 -> 19595 | G8: =SUMIF('Daily Trade Summary'!$A:$A,$A8,'Daily Trade Summary'!$L:$L) -> 5229.6774 | H8: =$G8*SST_Rate -> 679.85806 | I8: =$F8-$G8-$H8 -> 13685.465 | J8: =IF($D8=0,"N/A",$I8/$D8) -> 0.00085152458
A9: PPL-AUG | B9: =SUMIF('Daily Trade Summary'!$A:$A,$A9,'Daily Trade Summary'!$B:$B) -> 37000 | C9: =SUMIF('Daily Trade Summary'!$A:$A,$A9,'Daily Trade Summary'!$E:$E) -> 37000 | D9: =SUMIF('Daily Trade Summary'!$A:$A,$A9,'Daily Trade Summary'!$C:$C) -> 8881420 | E9: =SUMIF('Daily Trade Summary'!$A:$A,$A9,'Daily Trade Summary'!$F:$F) -> 8898330 | F9: =$E9-$D9 -> 16910 | G9: =SUMIF('Daily Trade Summary'!$A:$A,$A9,'Daily Trade Summary'!$L:$L) -> 2891.9572 | H9: =$G9*SST_Rate -> 375.95444 | I9: =$F9-$G9-$H9 -> 13642.088 | J9: =IF($D9=0,"N/A",$I9/$D9) -> 0.0015360256
A10: NRL-SEP | B10: =SUMIF('Daily Trade Summary'!$A:$A,$A10,'Daily Trade Summary'!$B:$B) -> 88500 | C10: =SUMIF('Daily Trade Summary'!$A:$A,$A10,'Daily Trade Summary'!$E:$E) -> 88500 | D10: =SUMIF('Daily Trade Summary'!$A:$A,$A10,'Daily Trade Summary'!$C:$C) -> 46865190 | E10: =SUMIF('Daily Trade Summary'!$A:$A,$A10,'Daily Trade Summary'!$F:$F) -> 46895670 | F10: =$E10-$D10 -> 30480 | G10: =SUMIF('Daily Trade Summary'!$A:$A,$A10,'Daily Trade Summary'!$L:$L) -> 15241.093 | H10: =$G10*SST_Rate -> 1981.3421 | I10: =$F10-$G10-$H10 -> 13257.565 | J10: =IF($D10=0,"N/A",$I10/$D10) -> 0.00028288726
A11: PRL-OCT | B11: =SUMIF('Daily Trade Summary'!$A:$A,$A11,'Daily Trade Summary'!$B:$B) -> 658500 | C11: =SUMIF('Daily Trade Summary'!$A:$A,$A11,'Daily Trade Summary'!$E:$E) -> 658500 | D11: =SUMIF('Daily Trade Summary'!$A:$A,$A11,'Daily Trade Summary'!$C:$C) -> 62249075 | E11: =SUMIF('Daily Trade Summary'!$A:$A,$A11,'Daily Trade Summary'!$F:$F) -> 62282360 | F11: =$E11-$D11 -> 33285 | G11: =SUMIF('Daily Trade Summary'!$A:$A,$A11,'Daily Trade Summary'!$L:$L) -> 20241.767 | H11: =$G11*SST_Rate -> 2631.4297 | I11: =$F11-$G11-$H11 -> 10411.803 | J11: =IF($D11=0,"N/A",$I11/$D11) -> 0.00016726037
A12: NRL-OCT | B12: =SUMIF('Daily Trade Summary'!$A:$A,$A12,'Daily Trade Summary'!$B:$B) -> 56500 | C12: =SUMIF('Daily Trade Summary'!$A:$A,$A12,'Daily Trade Summary'!$E:$E) -> 56500 | D12: =SUMIF('Daily Trade Summary'!$A:$A,$A12,'Daily Trade Summary'!$C:$C) -> 34719095 | E12: =SUMIF('Daily Trade Summary'!$A:$A,$A12,'Daily Trade Summary'!$F:$F) -> 34741665 | F12: =$E12-$D12 -> 22570 | G12: =SUMIF('Daily Trade Summary'!$A:$A,$A12,'Daily Trade Summary'!$L:$L) -> 11291.041 | H12: =$G12*SST_Rate -> 1467.8353 | I12: =$F12-$G12-$H12 -> 9811.1235 | J12: =IF($D12=0,"N/A",$I12/$D12) -> 0.00028258581
A13: FCCL-OCTB | B13: =SUMIF('Daily Trade Summary'!$A:$A,$A13,'Daily Trade Summary'!$B:$B) -> 30000 | C13: =SUMIF('Daily Trade Summary'!$A:$A,$A13,'Daily Trade Summary'!$E:$E) -> 30000 | D13: =SUMIF('Daily Trade Summary'!$A:$A,$A13,'Daily Trade Summary'!$C:$C) -> 1581000 | E13: =SUMIF('Daily Trade Summary'!$A:$A,$A13,'Daily Trade Summary'!$F:$F) -> 1585695 | F13: =$E13-$D13 -> 4695 | G13: =SUMIF('Daily Trade Summary'!$A:$A,$A13,'Daily Trade Summary'!$L:$L) -> 179.65 | H13: =$G13*SST_Rate -> 23.3545 | I13: =$F13-$G13-$H13 -> 4491.9955 | J13: =IF($D13=0,"N/A",$I13/$D13) -> 0.0028412369
A14: PTC-OCT | B14: =SUMIF('Daily Trade Summary'!$A:$A,$A14,'Daily Trade Summary'!$B:$B) -> 50000 | C14: =SUMIF('Daily Trade Summary'!$A:$A,$A14,'Daily Trade Summary'!$E:$E) -> 50000 | D14: =SUMIF('Daily Trade Summary'!$A:$A,$A14,'Daily Trade Summary'!$C:$C) -> 2751570 | E14: =SUMIF('Daily Trade Summary'!$A:$A,$A14,'Daily Trade Summary'!$F:$F) -> 2756225 | F14: =$E14-$D14 -> 4655 | G14: =SUMIF('Daily Trade Summary'!$A:$A,$A14,'Daily Trade Summary'!$L:$L) -> 207.85 | H14: =$G14*SST_Rate -> 27.0205 | I14: =$F14-$G14-$H14 -> 4420.1295 | J14: =IF($D14=0,"N/A",$I14/$D14) -> 0.0016064027
A15: PPL-OCTB | B15: =SUMIF('Daily Trade Summary'!$A:$A,$A15,'Daily Trade Summary'!$B:$B) -> 5000 | C15: =SUMIF('Daily Trade Summary'!$A:$A,$A15,'Daily Trade Summary'!$E:$E) -> 5000 | D15: =SUMIF('Daily Trade Summary'!$A:$A,$A15,'Daily Trade Summary'!$C:$C) -> 1065500 | E15: =SUMIF('Daily Trade Summary'!$A:$A,$A15,'Daily Trade Summary'!$F:$F) -> 1070000 | F15: =$E15-$D15 -> 4500 | G15: =SUMIF('Daily Trade Summary'!$A:$A,$A15,'Daily Trade Summary'!$L:$L) -> 347.75 | H15: =$G15*SST_Rate -> 45.2075 | I15: =$F15-$G15-$H15 -> 4107.0425 | J15: =IF($D15=0,"N/A",$I15/$D15) -> 0.0038545683
A16: PSO-OCT | B16: =SUMIF('Daily Trade Summary'!$A:$A,$A16,'Daily Trade Summary'!$B:$B) -> 12500 | C16: =SUMIF('Daily Trade Summary'!$A:$A,$A16,'Daily Trade Summary'!$E:$E) -> 12500 | D16: =SUMIF('Daily Trade Summary'!$A:$A,$A16,'Daily Trade Summary'!$C:$C) -> 4513315 | E16: =SUMIF('Daily Trade Summary'!$A:$A,$A16,'Daily Trade Summary'!$F:$F) -> 4518635 | F16: =$E16-$D16 -> 5320 | G16: =SUMIF('Daily Trade Summary'!$A:$A,$A16,'Daily Trade Summary'!$L:$L) -> 1468.5564 | H16: =$G16*SST_Rate -> 190.91233 | I16: =$F16-$G16-$H16 -> 3660.5313 | J16: =IF($D16=0,"N/A",$I16/$D16) -> 0.00081105159
A17: DGKC-SEP | B17: =SUMIF('Daily Trade Summary'!$A:$A,$A17,'Daily Trade Summary'!$B:$B) -> 26000 | C17: =SUMIF('Daily Trade Summary'!$A:$A,$A17,'Daily Trade Summary'!$E:$E) -> 26000 | D17: =SUMIF('Daily Trade Summary'!$A:$A,$A17,'Daily Trade Summary'!$C:$C) -> 5123920 | E17: =SUMIF('Daily Trade Summary'!$A:$A,$A17,'Daily Trade Summary'!$F:$F) -> 5129445 | F17: =$E17-$D17 -> 5525 | G17: =SUMIF('Daily Trade Summary'!$A:$A,$A17,'Daily Trade Summary'!$L:$L) -> 1667.0696 | H17: =$G17*SST_Rate -> 216.71905 | I17: =$F17-$G17-$H17 -> 3641.2113 | J17: =IF($D17=0,"N/A",$I17/$D17) -> 0.00071063001
... A60: GAL-SEP | B60: =SUMIF('Daily Trade Summary'!$A:$A,$A60,'Daily Trade Summary'!$B:$B) -> 3000 | C60: =SUMIF('Daily Trade Summary'!$A:$A,$A60,'Daily Trade Summary'!$E:$E) -> 3000 | D60: =SUMIF('Daily Trade Summary'!$A:$A,$A60,'Daily Trade Summary'!$C:$C) -> 1636990 | E60: =SUMIF('Daily Trade Summary'!$A:$A,$A60,'Daily Trade Summary'!$F:$F) -> 1635010 | F60: =$E60-$D60 -> -1980 | G60: =SUMIF('Daily Trade Summary'!$A:$A,$A60,'Daily Trade Summary'!$L:$L) -> 531.37825 | H60: =$G60*SST_Rate -> 69.079172 | I60: =$F60-$G60-$H60 -> -2580.4574 | J60: =IF($D60=0,"N/A",$I60/$D60) -> -0.0015763428
